<?xml version="1.0" encoding="UTF-8"?>
<testng-results ignored="0" total="4" passed="1" failed="2" skipped="1">
  <reporter-output>
    <line>
      <![CDATA[onStart]]>
    </line>
    <line>
      <![CDATA[onTestStart]]>
    </line>
    <line>
      <![CDATA[onTestFailedWithTimeout]]>
    </line>
    <line>
      <![CDATA[onTestStart]]>
    </line>
    <line>
      <![CDATA[Test case Ppassed]]>
    </line>
    <line>
      <![CDATA[onTestStart]]>
    </line>
    <line>
      <![CDATA[Test case Ffailed]]>
    </line>
    <line>
      <![CDATA[onTestStart]]>
    </line>
    <line>
      <![CDATA[onTestSkipped]]>
    </line>
    <line>
      <![CDATA[onFinish]]>
    </line>
  </reporter-output>
  <suite started-at="2024-07-05T13:32:27 IST" name="Default suite" finished-at="2024-07-05T13:32:34 IST" duration-ms="6665">
    <groups>
    </groups>
    <test started-at="2024-07-05T13:32:27 IST" name="Default test" finished-at="2024-07-05T13:32:34 IST" duration-ms="6665">
      <class name="listeners.TestCase">
        <test-method signature="testcase3()[pri:0, instance:listeners.TestCase@73700b80]" started-at="2024-07-05T13:32:27 IST" name="testcase3" finished-at="2024-07-05T13:32:28 IST" duration-ms="1040" status="FAIL">
          <exception class="org.testng.internal.thread.ThreadTimeoutException">
            <message>
              <![CDATA[Method listeners.TestCase.testcase3() didn't finish within the time-out 1000]]>
            </message>
            <full-stacktrace>
              <![CDATA[org.testng.internal.thread.ThreadTimeoutException: Method listeners.TestCase.testcase3() didn't finish within the time-out 1000
at org.testng.internal.MethodInvocationHelper.invokeWithTimeoutWithNewExecutor(MethodInvocationHelper.java:384)
at org.testng.internal.MethodInvocationHelper.invokeWithTimeout(MethodInvocationHelper.java:283)
at org.testng.internal.TestInvoker.invokeMethod(TestInvoker.java:604)
at org.testng.internal.TestInvoker.invokeTestMethod(TestInvoker.java:173)
at org.testng.internal.MethodRunner.runInSequence(MethodRunner.java:46)
at org.testng.internal.TestInvoker$MethodInvocationAgent.invoke(TestInvoker.java:824)
at org.testng.internal.TestInvoker.invokeTestMethods(TestInvoker.java:146)
at org.testng.internal.TestMethodWorker.invokeTestMethods(TestMethodWorker.java:146)
at org.testng.internal.TestMethodWorker.run(TestMethodWorker.java:128)
at java.base/java.util.ArrayList.forEach(ArrayList.java:1511)
at org.testng.TestRunner.privateRun(TestRunner.java:794)
at org.testng.TestRunner.run(TestRunner.java:596)
at org.testng.SuiteRunner.runTest(SuiteRunner.java:377)
at org.testng.SuiteRunner.runSequentially(SuiteRunner.java:371)
at org.testng.SuiteRunner.privateRun(SuiteRunner.java:332)
at org.testng.SuiteRunner.run(SuiteRunner.java:276)
at org.testng.SuiteRunnerWorker.runSuite(SuiteRunnerWorker.java:53)
at org.testng.SuiteRunnerWorker.run(SuiteRunnerWorker.java:96)
at org.testng.TestNG.runSuitesSequentially(TestNG.java:1212)
at org.testng.TestNG.runSuitesLocally(TestNG.java:1134)
at org.testng.TestNG.runSuites(TestNG.java:1063)
at org.testng.TestNG.run(TestNG.java:1031)
at org.testng.remote.AbstractRemoteTestNG.run(AbstractRemoteTestNG.java:115)
at org.testng.remote.RemoteTestNG.initAndRun(RemoteTestNG.java:293)
at org.testng.remote.RemoteTestNG.main(RemoteTestNG.java:91)
]]>
            </full-stacktrace>
          </exception> <!-- org.testng.internal.thread.ThreadTimeoutException -->
          <reporter-output>
            <line>
              <![CDATA[onTestStart]]>
            </line>
            <line>
              <![CDATA[onTestFailedWithTimeout]]>
            </line>
          </reporter-output>
        </test-method> <!-- testcase3 -->
        <test-method signature="testcase1()[pri:0, instance:listeners.TestCase@73700b80]" started-at="2024-07-05T13:32:28 IST" name="testcase1" finished-at="2024-07-05T13:32:33 IST" duration-ms="4720" status="PASS">
          <reporter-output>
            <line>
              <![CDATA[onTestStart]]>
            </line>
            <line>
              <![CDATA[Test case Ppassed]]>
            </line>
          </reporter-output>
        </test-method> <!-- testcase1 -->
        <test-method signature="testcase2()[pri:0, instance:listeners.TestCase@73700b80]" started-at="2024-07-05T13:32:34 IST" name="testcase2" finished-at="2024-07-05T13:32:34 IST" duration-ms="5" status="FAIL">
          <exception class="java.lang.AssertionError">
            <message>
              <![CDATA[expected [true] but found [false]]]>
            </message>
            <full-stacktrace>
              <![CDATA[java.lang.AssertionError: expected [true] but found [false]
at org.testng.Assert.fail(Assert.java:99)
at org.testng.Assert.failNotEquals(Assert.java:1037)
at org.testng.Assert.assertTrue(Assert.java:45)
at org.testng.Assert.assertTrue(Assert.java:55)
at listeners.TestCase.testcase2(TestCase.java:22)
at java.base/jdk.internal.reflect.NativeMethodAccessorImpl.invoke0(Native Method)
at java.base/jdk.internal.reflect.NativeMethodAccessorImpl.invoke(NativeMethodAccessorImpl.java:77)
at java.base/jdk.internal.reflect.DelegatingMethodAccessorImpl.invoke(DelegatingMethodAccessorImpl.java:43)
at java.base/java.lang.reflect.Method.invoke(Method.java:568)
at org.testng.internal.MethodInvocationHelper.invokeMethod(MethodInvocationHelper.java:133)
at org.testng.internal.TestInvoker.invokeMethod(TestInvoker.java:598)
at org.testng.internal.TestInvoker.invokeTestMethod(TestInvoker.java:173)
at org.testng.internal.MethodRunner.runInSequence(MethodRunner.java:46)
at org.testng.internal.TestInvoker$MethodInvocationAgent.invoke(TestInvoker.java:824)
at org.testng.internal.TestInvoker.invokeTestMethods(TestInvoker.java:146)
at org.testng.internal.TestMethodWorker.invokeTestMethods(TestMethodWorker.java:146)
at org.testng.internal.TestMethodWorker.run(TestMethodWorker.java:128)
at java.base/java.util.ArrayList.forEach(ArrayList.java:1511)
at org.testng.TestRunner.privateRun(TestRunner.java:794)
at org.testng.TestRunner.run(TestRunner.java:596)
at org.testng.SuiteRunner.runTest(SuiteRunner.java:377)
at org.testng.SuiteRunner.runSequentially(SuiteRunner.java:371)
at org.testng.SuiteRunner.privateRun(SuiteRunner.java:332)
at org.testng.SuiteRunner.run(SuiteRunner.java:276)
at org.testng.SuiteRunnerWorker.runSuite(SuiteRunnerWorker.java:53)
at org.testng.SuiteRunnerWorker.run(SuiteRunnerWorker.java:96)
at org.testng.TestNG.runSuitesSequentially(TestNG.java:1212)
at org.testng.TestNG.runSuitesLocally(TestNG.java:1134)
at org.testng.TestNG.runSuites(TestNG.java:1063)
at org.testng.TestNG.run(TestNG.java:1031)
at org.testng.remote.AbstractRemoteTestNG.run(AbstractRemoteTestNG.java:115)
at org.testng.remote.RemoteTestNG.initAndRun(RemoteTestNG.java:293)
at org.testng.remote.RemoteTestNG.main(RemoteTestNG.java:91)
]]>
            </full-stacktrace>
          </exception> <!-- java.lang.AssertionError -->
          <reporter-output>
            <line>
              <![CDATA[onTestStart]]>
            </line>
            <line>
              <![CDATA[Test case Ffailed]]>
            </line>
          </reporter-output>
        </test-method> <!-- testcase2 -->
        <test-method signature="testcase4()[pri:0, instance:listeners.TestCase@73700b80]" started-at="2024-07-05T13:32:34 IST" name="testcase4" finished-at="2024-07-05T13:32:34 IST" depends-on-methods="listeners.TestCase.testcase3" duration-ms="0" status="SKIP">
          <exception class="java.lang.Throwable">
            <message>
              <![CDATA[Method TestCase.testcase4()[pri:0, instance:listeners.TestCase@73700b80] depends on not successfully finished methods]]>
            </message>
            <full-stacktrace>
              <![CDATA[java.lang.Throwable: Method TestCase.testcase4()[pri:0, instance:listeners.TestCase@73700b80] depends on not successfully finished methods
at org.testng.internal.TestInvoker.invokeTestMethods(TestInvoker.java:102)
at org.testng.internal.TestMethodWorker.invokeTestMethods(TestMethodWorker.java:146)
at org.testng.internal.TestMethodWorker.run(TestMethodWorker.java:128)
at java.base/java.util.ArrayList.forEach(ArrayList.java:1511)
at org.testng.TestRunner.privateRun(TestRunner.java:794)
at org.testng.TestRunner.run(TestRunner.java:596)
at org.testng.SuiteRunner.runTest(SuiteRunner.java:377)
at org.testng.SuiteRunner.runSequentially(SuiteRunner.java:371)
at org.testng.SuiteRunner.privateRun(SuiteRunner.java:332)
at org.testng.SuiteRunner.run(SuiteRunner.java:276)
at org.testng.SuiteRunnerWorker.runSuite(SuiteRunnerWorker.java:53)
at org.testng.SuiteRunnerWorker.run(SuiteRunnerWorker.java:96)
at org.testng.TestNG.runSuitesSequentially(TestNG.java:1212)
at org.testng.TestNG.runSuitesLocally(TestNG.java:1134)
at org.testng.TestNG.runSuites(TestNG.java:1063)
at org.testng.TestNG.run(TestNG.java:1031)
at org.testng.remote.AbstractRemoteTestNG.run(AbstractRemoteTestNG.java:115)
at org.testng.remote.RemoteTestNG.initAndRun(RemoteTestNG.java:293)
at org.testng.remote.RemoteTestNG.main(RemoteTestNG.java:91)
]]>
            </full-stacktrace>
          </exception> <!-- java.lang.Throwable -->
          <reporter-output>
            <line>
              <![CDATA[onTestSkipped]]>
            </line>
            <line>
              <![CDATA[onFinish]]>
            </line>
          </reporter-output>
        </test-method> <!-- testcase4 -->
      </class> <!-- listeners.TestCase -->
    </test> <!-- Default test -->
  </suite> <!-- Default suite -->
</testng-results>
